<?xml version="1.0" ?>
<sdf version="1.9">
  <model name="spirob_arm">
    <static>0</static>
    <link name="base_link">
      <pose degrees="true">0 0 0 0 0 0</pose>
      <inertial auto="true" />
      <collision name="collision">
        <pose degrees="true">0 0 0 0 0 0</pose>
        <density>10000</density>
        <geometry>
          <box>
            <size>0.1 0.1 0.1</size>
          </box>
        </geometry>
      </collision>
      <visual name="visual">
        <pose degrees="true">0 0 0 0 0 0</pose>
        <geometry>
          <box>
            <size>0.1 0.1 0.1</size>
          </box>
        </geometry>
        <material>
          <ambient>0.5 0.5 0.5</ambient>
          <diffuse>0.5 0.5 0.5</diffuse>
          <specular>0.1 0.1 0.1</specular>
        </material>
      </visual>
    </link>
    <joint name="joint01" type="fixed">
      <pose degrees="true" relative_to="base_link">0.05 0 0 0 0 0</pose>
      <parent>base_link</parent>
      <child>link1</child>
    </joint>

    <link name="link1">
      <!--<pose degrees="true">0.464082120 0 0 0 0 0</pose>-->
      <pose degrees="true" relative_to="joint01">0 0 0 0 0 0</pose>
      <inertial auto="true" />
      <collision name="collision">
        <pose degrees="true">0 0 0 0 -90 180</pose>
        <density>1100</density>
        <geometry>
          <mesh>
            <scale>0.001000000 0.001000000 0.001000000</scale>
            <uri>meshes/baselink.stl</uri>
          </mesh>
        </geometry>
      </collision>
      <visual name="visual">
        <pose degrees="true">0 0 0 0 -90 180</pose>
        <geometry>
          <mesh>
            <scale>0.001000000 0.001000000 0.001000000</scale>
            <uri>meshes/baselink.stl</uri>
          </mesh>
        </geometry>
        <material>
          <ambient>0.5 0.5 0.5</ambient>
          <diffuse>0.5 0.5 0.5</diffuse>
          <specular>0.1 0.1 0.1</specular>
        </material>
      </visual>
    </link>
    <link name="link2">
      <pose degrees="true" relative_to="joint12">0 0 0 0 0 0</pose>
      <inertial auto="true" />
      <collision name="collision">
        <density>1100</density>
        <pose degrees="true">0 0 0 0 -90 180</pose>
        <geometry>
          <mesh>
            <scale>0.000911774 0.000911774 0.000911774</scale>
            <uri>meshes/baselink.stl</uri>
          </mesh>
        </geometry>
      </collision>
      <visual name="visual">
        <pose degrees="true">0 0 0 0 -90 180</pose>
        <geometry>
          <mesh>
            <scale>0.000911774 0.000911774 0.000911774</scale>
            <uri>meshes/baselink.stl</uri>
          </mesh>
        </geometry>
        <material>
          <ambient>0.5 0.5 0.5</ambient>
          <diffuse>0.5 0.5 0.5</diffuse>
          <specular>0.1 0.1 0.1</specular>
        </material>
      </visual>
    </link>
    <link name="link3">
      <pose degrees="true" relative_to="joint23">0 0 0 0 0 0</pose>
      <inertial auto="true" />
      <collision name="collision">
        <pose degrees="true">0 0 0 0 -90 180</pose>
        <density>1100</density>
        <geometry>
          <mesh>
            <scale>0.000831332 0.000831332 0.000831332</scale>
            <uri>meshes/baselink.stl</uri>
          </mesh>
        </geometry>
      </collision>
      <visual name="visual">
        <pose degrees="true">0 0 0 0 -90 180</pose>
        <geometry>
          <mesh>
            <scale>0.000831332 0.000831332 0.000831332</scale>
            <uri>meshes/baselink.stl</uri>
          </mesh>
        </geometry>
        <material>
          <ambient>0.5 0.5 0.5</ambient>
          <diffuse>0.5 0.5 0.5</diffuse>
          <specular>0.1 0.1 0.1</specular>
        </material>
      </visual>
    </link>
    <link name="link4">
      <pose degrees="true" relative_to="joint34">0 0 0 0 0 0</pose>
      <inertial auto="true" />
      <collision name="collision">
        <pose degrees="true">0 0 0 0 -90 180</pose>
        <density>1100</density>
        <geometry>
          <mesh>
            <scale>0.000757987 0.000757987 0.000757987</scale>
            <uri>meshes/baselink.stl</uri>
          </mesh>
        </geometry>
      </collision>
      <visual name="visual">
        <pose degrees="true">0 0 0 0 -90 180</pose>
        <geometry>
          <mesh>
            <scale>0.000757987 0.000757987 0.000757987</scale>
            <uri>meshes/baselink.stl</uri>
          </mesh>
        </geometry>
        <material>
          <ambient>0.5 0.5 0.5</ambient>
          <diffuse>0.5 0.5 0.5</diffuse>
          <specular>0.1 0.1 0.1</specular>
        </material>
      </visual>
    </link>
    <link name="link5">
      <pose degrees="true" relative_to="joint45">0 0 0 0 0 0</pose>
      <inertial auto="true" />
      <collision name="collision">
        <pose degrees="true">0 0 0 0 -90 180</pose>
        <density>1100</density>
        <geometry>
          <mesh>
            <scale>0.000691113 0.000691113 0.000691113</scale>
            <uri>meshes/baselink.stl</uri>
          </mesh>
        </geometry>
      </collision>
      <visual name="visual">
        <pose degrees="true">0 0 0 0 -90 180</pose>
        <geometry>
          <mesh>
            <scale>0.000691113 0.000691113 0.000691113</scale>
            <uri>meshes/baselink.stl</uri>
          </mesh>
        </geometry>
        <material>
          <ambient>0.5 0.5 0.5</ambient>
          <diffuse>0.5 0.5 0.5</diffuse>
          <specular>0.1 0.1 0.1</specular>
        </material>
      </visual>
    </link>
    <link name="link6">
      <pose degrees="true" relative_to="joint56">0 0 0 0 0 0</pose>
      <inertial auto="true" />
      <collision name="collision">
        <pose degrees="true">0 0 0 0 -90 180</pose>
        <density>1100</density>
        <geometry>
          <mesh>
            <scale>0.000630139 0.000630139 0.000630139</scale>
            <uri>meshes/baselink.stl</uri>
          </mesh>
        </geometry>
      </collision>
      <visual name="visual">
        <pose degrees="true">0 0 0 0 -90 180</pose>
        <geometry>
          <mesh>
            <scale>0.000630139 0.000630139 0.000630139</scale>
            <uri>meshes/baselink.stl</uri>
          </mesh>
        </geometry>
        <material>
          <ambient>0.5 0.5 0.5</ambient>
          <diffuse>0.5 0.5 0.5</diffuse>
          <specular>0.1 0.1 0.1</specular>
        </material>
      </visual>
    </link>
    <link name="link7">
      <pose degrees="true" relative_to="joint67">0 0 0 0 0 0</pose>
      <inertial auto="true" />
      <collision name="collision">
        <pose degrees="true">0 0 0 0 -90 180</pose>
        <density>1100</density>
        <geometry>
          <mesh>
            <scale>0.000574545 0.000574545 0.000574545</scale>
            <uri>meshes/baselink.stl</uri>
          </mesh>
        </geometry>
      </collision>
      <visual name="visual">
        <pose degrees="true">0 0 0 0 -90 180</pose>
        <geometry>
          <mesh>
            <scale>0.000574545 0.000574545 0.000574545</scale>
            <uri>meshes/baselink.stl</uri>
          </mesh>
        </geometry>
        <material>
          <ambient>0.5 0.5 0.5</ambient>
          <diffuse>0.5 0.5 0.5</diffuse>
          <specular>0.1 0.1 0.1</specular>
        </material>
      </visual>
    </link>
    <link name="link8">
      <pose degrees="true" relative_to="joint78">0 0 0 0 0 0</pose>
      <inertial auto="true" />
      <collision name="collision">
        <pose degrees="true">0 0 0 0 -90 180</pose>
        <density>1100</density>
        <geometry>
          <mesh>
            <scale>0.000523855 0.000523855 0.000523855</scale>
            <uri>meshes/baselink.stl</uri>
          </mesh>
        </geometry>
      </collision>
      <visual name="visual">
        <pose degrees="true">0 0 0 0 -90 180</pose>
        <geometry>
          <mesh>
            <scale>0.000523855 0.000523855 0.000523855</scale>
            <uri>meshes/baselink.stl</uri>
          </mesh>
        </geometry>
        <material>
          <ambient>0.5 0.5 0.5</ambient>
          <diffuse>0.5 0.5 0.5</diffuse>
          <specular>0.1 0.1 0.1</specular>
        </material>
      </visual>
    </link>
    <link name="link9">
      <pose degrees="true" relative_to="joint89">0 0 0 0 0 0</pose>
      <inertial auto="true" />
      <collision name="collision">
        <pose degrees="true">0 0 0 0 -90 180</pose>
        <density>1100</density>
        <geometry>
          <mesh>
            <scale>0.000477638 0.000477638 0.000477638</scale>
            <uri>meshes/baselink.stl</uri>
          </mesh>
        </geometry>
      </collision>
      <visual name="visual">
        <pose degrees="true">0 0 0 0 -90 180</pose>
        <geometry>
          <mesh>
            <scale>0.000477638 0.000477638 0.000477638</scale>
            <uri>meshes/baselink.stl</uri>
          </mesh>
        </geometry>
        <material>
          <ambient>0.5 0.5 0.5</ambient>
          <diffuse>0.5 0.5 0.5</diffuse>
          <specular>0.1 0.1 0.1</specular>
        </material>
      </visual>
    </link>
    <link name="link10">
      <pose degrees="true" relative_to="joint910">0 0 0 0 0 0</pose>
      <inertial auto="true" />
      <collision name="collision">
        <pose degrees="true">0 0 0 0 -90 180</pose>
        <density>1100</density>
        <geometry>
          <mesh>
            <scale>0.000435498 0.000435498 0.000435498</scale>
            <uri>meshes/baselink.stl</uri>
          </mesh>
        </geometry>
      </collision>
      <visual name="visual">
        <pose degrees="true">0 0 0 0 -90 180</pose>
        <geometry>
          <mesh>
            <scale>0.000435498 0.000435498 0.000435498</scale>
            <uri>meshes/baselink.stl</uri>
          </mesh>
        </geometry>
        <material>
          <ambient>0.5 0.5 0.5</ambient>
          <diffuse>0.5 0.5 0.5</diffuse>
          <specular>0.1 0.1 0.1</specular>
        </material>
      </visual>
    </link>
    <link name="link11">
      <pose degrees="true" relative_to="joint1011">0 0 0 0 0 0</pose>
      <inertial auto="true" />
      <collision name="collision">
        <pose degrees="true">0 0 0 0 -90 180</pose>
        <density>1100</density>
        <geometry>
          <mesh>
            <scale>0.000397076 0.000397076 0.000397076</scale>
            <uri>meshes/baselink.stl</uri>
          </mesh>
        </geometry>
      </collision>
      <visual name="visual">
        <pose degrees="true">0 0 0 0 -90 180</pose>
        <geometry>
          <mesh>
            <scale>0.000397076 0.000397076 0.000397076</scale>
            <uri>meshes/baselink.stl</uri>
          </mesh>
        </geometry>
        <material>
          <ambient>0.5 0.5 0.5</ambient>
          <diffuse>0.5 0.5 0.5</diffuse>
          <specular>0.1 0.1 0.1</specular>
        </material>
      </visual>
    </link>
    <link name="link12">
      <pose degrees="true" relative_to="joint1112">0 0 0 0 0 0</pose>
      <inertial auto="true" />
      <collision name="collision">
        <pose degrees="true">0 0 0 0 -90 180</pose>
        <density>1100</density>
        <geometry>
          <mesh>
            <scale>0.000362043 0.000362043 0.000362043</scale>
            <uri>meshes/baselink.stl</uri>
          </mesh>
        </geometry>
      </collision>
      <visual name="visual">
        <pose degrees="true">0 0 0 0 -90 180</pose>
        <geometry>
          <mesh>
            <scale>0.000362043 0.000362043 0.000362043</scale>
            <uri>meshes/baselink.stl</uri>
          </mesh>
        </geometry>
        <material>
          <ambient>0.5 0.5 0.5</ambient>
          <diffuse>0.5 0.5 0.5</diffuse>
          <specular>0.1 0.1 0.1</specular>
        </material>
      </visual>
    </link>
    <link name="link13">
      <pose degrees="true" relative_to="joint1213">0 0 0 0 0 0</pose>
      <inertial auto="true" />
      <collision name="collision">
        <pose degrees="true">0 0 0 0 -90 180</pose>
        <density>1100</density>
        <geometry>
          <mesh>
            <scale>0.000330102 0.000330102 0.000330102</scale>
            <uri>meshes/baselink.stl</uri>
          </mesh>
        </geometry>
      </collision>
      <visual name="visual">
        <pose degrees="true">0 0 0 0 -90 180</pose>
        <geometry>
          <mesh>
            <scale>0.000330102 0.000330102 0.000330102</scale>
            <uri>meshes/baselink.stl</uri>
          </mesh>
        </geometry>
        <material>
          <ambient>0.5 0.5 0.5</ambient>
          <diffuse>0.5 0.5 0.5</diffuse>
          <specular>0.1 0.1 0.1</specular>
        </material>
      </visual>
    </link>
    <link name="link14">
      <pose degrees="true" relative_to="joint1314">0 0 0 0 0 0</pose>
      <inertial auto="true" />
      <collision name="collision">
        <pose degrees="true">0 0 0 0 -90 180</pose>
        <density>1100</density>
        <geometry>
          <mesh>
            <scale>0.000300978 0.000300978 0.000300978</scale>
            <uri>meshes/baselink.stl</uri>
          </mesh>
        </geometry>
      </collision>
      <visual name="visual">
        <pose degrees="true">0 0 0 0 -90 180</pose>
        <geometry>
          <mesh>
            <scale>0.000300978 0.000300978 0.000300978</scale>
            <uri>meshes/baselink.stl</uri>
          </mesh>
        </geometry>
        <material>
          <ambient>0.5 0.5 0.5</ambient>
          <diffuse>0.5 0.5 0.5</diffuse>
          <specular>0.1 0.1 0.1</specular>
        </material>
      </visual>
    </link>
    <link name="link15">
      <pose degrees="true" relative_to="joint1415">0 0 0 0 0 0</pose>
      <inertial auto="true" />
      <collision name="collision">
        <pose degrees="true">0 0 0 0 -90 180</pose>
        <density>1100</density>
        <geometry>
          <mesh>
            <scale>0.000274424 0.000274424 0.000274424</scale>
            <uri>meshes/baselink.stl</uri>
          </mesh>
        </geometry>
      </collision>
      <visual name="visual">
        <pose degrees="true">0 0 0 0 -90 180</pose>
        <geometry>
          <mesh>
            <scale>0.000274424 0.000274424 0.000274424</scale>
            <uri>meshes/baselink.stl</uri>
          </mesh>
        </geometry>
        <material>
          <ambient>0.5 0.5 0.5</ambient>
          <diffuse>0.5 0.5 0.5</diffuse>
          <specular>0.1 0.1 0.1</specular>
        </material>
      </visual>
    </link>
    <link name="link16">
      <pose degrees="true" relative_to="joint1516">0 0 0 0 0 0</pose>
      <inertial auto="true" />
      <collision name="collision">
        <pose degrees="true">0 0 0 0 -90 180</pose>
        <density>1100</density>
        <geometry>
          <mesh>
            <scale>0.000250213 0.000250213 0.000250213</scale>
            <uri>meshes/baselink.stl</uri>
          </mesh>
        </geometry>
      </collision>
      <visual name="visual">
        <pose degrees="true">0 0 0 0 -90 180</pose>
        <geometry>
          <mesh>
            <scale>0.000250213 0.000250213 0.000250213</scale>
            <uri>meshes/baselink.stl</uri>
          </mesh>
        </geometry>
        <material>
          <ambient>0.5 0.5 0.5</ambient>
          <diffuse>0.5 0.5 0.5</diffuse>
          <specular>0.1 0.1 0.1</specular>
        </material>
      </visual>
    </link>
    <link name="link17">
      <pose degrees="true" relative_to="joint1617">0 0 0 0 0 0</pose>
      <inertial auto="true" />
      <collision name="collision">
        <pose degrees="true">0 0 0 0 -90 180</pose>
        <density>1100</density>
        <geometry>
          <mesh>
            <scale>0.000228138 0.000228138 0.000228138</scale>
            <uri>meshes/baselink.stl</uri>
          </mesh>
        </geometry>
      </collision>
      <visual name="visual">
        <pose degrees="true">0 0 0 0 -90 180</pose>
        <geometry>
          <mesh>
            <scale>0.000228138 0.000228138 0.000228138</scale>
            <uri>meshes/baselink.stl</uri>
          </mesh>
        </geometry>
        <material>
          <ambient>0.5 0.5 0.5</ambient>
          <diffuse>0.5 0.5 0.5</diffuse>
          <specular>0.1 0.1 0.1</specular>
        </material>
      </visual>
    </link>
    <link name="link18">
      <pose degrees="true" relative_to="joint1718">0 0 0 0 0 0</pose>
      <inertial auto="true" />
      <collision name="collision">
        <pose degrees="true">0 0 0 0 -90 180</pose>
        <density>1100</density>
        <geometry>
          <mesh>
            <scale>0.000208010 0.000208010 0.000208010</scale>
            <uri>meshes/baselink.stl</uri>
          </mesh>
        </geometry>
      </collision>
      <visual name="visual">
        <pose degrees="true">0 0 0 0 -90 180</pose>
        <geometry>
          <mesh>
            <scale>0.000208010 0.000208010 0.000208010</scale>
            <uri>meshes/baselink.stl</uri>
          </mesh>
        </geometry>
        <material>
          <ambient>0.5 0.5 0.5</ambient>
          <diffuse>0.5 0.5 0.5</diffuse>
          <specular>0.1 0.1 0.1</specular>
        </material>
      </visual>
    </link>
    <link name="link19">
      <pose degrees="true" relative_to="joint1819">0 0 0 0 0 0</pose>
      <inertial auto="true" />
      <collision name="collision">
        <pose degrees="true">0 0 0 0 -90 180</pose>
        <density>1100</density>
        <geometry>
          <mesh>
            <scale>0.000189658 0.000189658 0.000189658</scale>
            <uri>meshes/baselink.stl</uri>
          </mesh>
        </geometry>
      </collision>
      <visual name="visual">
        <pose degrees="true">0 0 0 0 -90 180</pose>
        <geometry>
          <mesh>
            <scale>0.000189658 0.000189658 0.000189658</scale>
            <uri>meshes/baselink.stl</uri>
          </mesh>
        </geometry>
        <material>
          <ambient>0.5 0.5 0.5</ambient>
          <diffuse>0.5 0.5 0.5</diffuse>
          <specular>0.1 0.1 0.1</specular>
        </material>
      </visual>
    </link>
    <link name="link20">
      <pose degrees="true" relative_to="joint1920">0 0 0 0 0 0</pose>
      <inertial auto="true" />
      <collision name="collision">
        <pose degrees="true">0 0 0 0 -90 180</pose>
        <density>1100</density>
        <geometry>
          <mesh>
            <scale>0.000172926 0.000172926 0.000172926</scale>
            <uri>meshes/baselink.stl</uri>
          </mesh>
        </geometry>
      </collision>
      <visual name="visual">
        <pose degrees="true">0 0 0 0 -90 180</pose>
        <geometry>
          <mesh>
            <scale>0.000172926 0.000172926 0.000172926</scale>
            <uri>meshes/baselink.stl</uri>
          </mesh>
        </geometry>
        <material>
          <ambient>0.5 0.5 0.5</ambient>
          <diffuse>0.5 0.5 0.5</diffuse>
          <specular>0.1 0.1 0.1</specular>
        </material>
      </visual>
    </link>
    <link name="link21">
      <pose degrees="true" relative_to="joint2021">0 0 0 0 0 0</pose>
      <inertial auto="true" />
      <collision name="collision">
        <pose degrees="true">0 0 0 0 -90 180</pose>
        <density>1100</density>
        <geometry>
          <mesh>
            <scale>0.000157669 0.000157669 0.000157669</scale>
            <uri>meshes/baselink.stl</uri>
          </mesh>
        </geometry>
      </collision>
      <visual name="visual">
        <pose degrees="true">0 0 0 0 -90 180</pose>
        <geometry>
          <mesh>
            <scale>0.000157669 0.000157669 0.000157669</scale>
            <uri>meshes/baselink.stl</uri>
          </mesh>
        </geometry>
        <material>
          <ambient>0.5 0.5 0.5</ambient>
          <diffuse>0.5 0.5 0.5</diffuse>
          <specular>0.1 0.1 0.1</specular>
        </material>
      </visual>
    </link>
    <link name="link22">
      <pose degrees="true" relative_to="joint2122">0 0 0 0 0 0</pose>
      <inertial auto="true" />
      <collision name="collision">
        <pose degrees="true">0 0 0 0 -90 180</pose>
        <density>1100</density>
        <geometry>
          <mesh>
            <scale>0.000143759 0.000143759 0.000143759</scale>
            <uri>meshes/baselink.stl</uri>
          </mesh>
        </geometry>
      </collision>
      <visual name="visual">
        <pose degrees="true">0 0 0 0 -90 180</pose>
        <geometry>
          <mesh>
            <scale>0.000143759 0.000143759 0.000143759</scale>
            <uri>meshes/baselink.stl</uri>
          </mesh>
        </geometry>
        <material>
          <ambient>0.5 0.5 0.5</ambient>
          <diffuse>0.5 0.5 0.5</diffuse>
          <specular>0.1 0.1 0.1</specular>
        </material>
      </visual>
    </link>
    <link name="link23">
      <pose degrees="true" relative_to="joint2223">0 0 0 0 0 0</pose>
      <inertial auto="true" />
      <collision name="collision">
        <pose degrees="true">0 0 0 0 -90 180</pose>
        <density>1100</density>
        <geometry>
          <mesh>
            <scale>0.000131075 0.000131075 0.000131075</scale>
            <uri>meshes/baselink.stl</uri>
          </mesh>
        </geometry>
      </collision>
      <visual name="visual">
        <pose degrees="true">0 0 0 0 -90 180</pose>
        <geometry>
          <mesh>
            <scale>0.000131075 0.000131075 0.000131075</scale>
            <uri>meshes/baselink.stl</uri>
          </mesh>
        </geometry>
        <material>
          <ambient>0.5 0.5 0.5</ambient>
          <diffuse>0.5 0.5 0.5</diffuse>
          <specular>0.1 0.1 0.1</specular>
        </material>
      </visual>
    </link>
    <link name="link24">
      <pose degrees="true" relative_to="joint2324">0 0 0 0 0 0</pose>
      <inertial auto="true" />
      <collision name="collision">
        <pose degrees="true">0 0 0 0 -90 180</pose>
        <density>1100</density>
        <geometry>
          <mesh>
            <scale>0.000119511 0.000119511 0.000119511</scale>
            <uri>meshes/baselink.stl</uri>
          </mesh>
        </geometry>
      </collision>
      <visual name="visual">
        <pose degrees="true">0 0 0 0 -90 180</pose>
        <geometry>
          <mesh>
            <scale>0.000119511 0.000119511 0.000119511</scale>
            <uri>meshes/baselink.stl</uri>
          </mesh>
        </geometry>
        <material>
          <ambient>0.5 0.5 0.5</ambient>
          <diffuse>0.5 0.5 0.5</diffuse>
          <specular>0.1 0.1 0.1</specular>
        </material>
      </visual>
    </link>

    <joint name="joint12" type="revolute">
      <pose degrees="true" relative_to="link1">0.045951152 0 0 0 0 0</pose>
      <parent>link1</parent>
      <child>link2</child>
      <axis>
        <xyz>0 0 1</xyz>
        <limit>
          <lower>-0.523598776</lower>
          <upper>0.523598776</upper>
        </limit>
        <dynamics>
          <damping>0.01</damping>
        </dynamics>
      </axis>
    </joint>
    <joint name="joint23" type="revolute">
      <pose degrees="true" relative_to="link2">0.041897079 0 0 0 0 0</pose>
      <parent>link2</parent>
      <child>link3</child>
      <axis>
        <xyz>0 0 1</xyz>
        <limit>
          <lower>-0.523598776</lower>
          <upper>0.523598776</upper>
        </limit>
        <dynamics>
          <damping>0.01</damping>
        </dynamics>
      </axis>
    </joint>
    <joint name="joint34" type="revolute">
      <pose degrees="true" relative_to="link3">0.038200679 0 0 0 0 0</pose>
      <parent>link3</parent>
      <child>link4</child>
      <axis>
        <xyz>0 0 1</xyz>
        <limit>
          <lower>-0.523598776</lower>
          <upper>0.523598776</upper>
        </limit>
        <dynamics>
          <damping>0.01</damping>
        </dynamics>
      </axis>
    </joint>
    <joint name="joint45" type="revolute">
      <pose degrees="true" relative_to="link4">0.034830396 0 0 0 0 0</pose>
      <parent>link4</parent>
      <child>link5</child>
      <axis>
        <xyz>0 0 1</xyz>
        <limit>
          <lower>-0.523598776</lower>
          <upper>0.523598776</upper>
        </limit>
        <dynamics>
          <damping>0.01</damping>
        </dynamics>
      </axis>
    </joint>
    <joint name="joint56" type="revolute">
      <pose degrees="true" relative_to="link5">0.031757459 0 0 0 0 0</pose>
      <parent>link5</parent>
      <child>link6</child>
      <axis>
        <xyz>0 0 1</xyz>
        <limit>
          <lower>-0.523598776</lower>
          <upper>0.523598776</upper>
        </limit>
        <dynamics>
          <damping>0.01</damping>
        </dynamics>
      </axis>
    </joint>
    <joint name="joint67" type="revolute">
      <pose degrees="true" relative_to="link6">0.028955634 0 0 0 0 0</pose>
      <parent>link6</parent>
      <child>link7</child>
      <axis>
        <xyz>0 0 1</xyz>
        <limit>
          <lower>-0.523598776</lower>
          <upper>0.523598776</upper>
        </limit>
        <dynamics>
          <damping>0.01</damping>
        </dynamics>
      </axis>
    </joint>
    <joint name="joint78" type="revolute">
      <pose degrees="true" relative_to="link7">0.026401003 0 0 0 0 0</pose>
      <parent>link7</parent>
      <child>link8</child>
      <axis>
        <xyz>0 0 1</xyz>
        <limit>
          <lower>-0.523598776</lower>
          <upper>0.523598776</upper>
        </limit>
        <dynamics>
          <damping>0.01</damping>
        </dynamics>
      </axis>
    </joint>
    <joint name="joint89" type="revolute">
      <pose degrees="true" relative_to="link8">0.024071755 0 0 0 0 0</pose>
      <parent>link8</parent>
      <child>link9</child>
      <axis>
        <xyz>0 0 1</xyz>
        <limit>
          <lower>-0.523598776</lower>
          <upper>0.523598776</upper>
        </limit>
        <dynamics>
          <damping>0.01</damping>
        </dynamics>
      </axis>
    </joint>
    <joint name="joint910" type="revolute">
      <pose degrees="true" relative_to="link9">0.021948007 0 0 0 0 0</pose>
      <parent>link9</parent>
      <child>link10</child>
      <axis>
        <xyz>0 0 1</xyz>
        <limit>
          <lower>-0.523598776</lower>
          <upper>0.523598776</upper>
        </limit>
        <dynamics>
          <damping>0.01</damping>
        </dynamics>
      </axis>
    </joint>
    <joint name="joint1011" type="revolute">
      <pose degrees="true" relative_to="link10">0.020011628 0 0 0 0 0</pose>
      <parent>link10</parent>
      <child>link11</child>
      <axis>
        <xyz>0 0 1</xyz>
        <limit>
          <lower>-0.523598776</lower>
          <upper>0.523598776</upper>
        </limit>
        <dynamics>
          <damping>0.01</damping>
        </dynamics>
      </axis>
    </joint>
    <joint name="joint1112" type="revolute">
      <pose degrees="true" relative_to="link11">0.018246088 0 0 0 0 0</pose>
      <parent>link11</parent>
      <child>link12</child>
      <axis>
        <xyz>0 0 1</xyz>
        <limit>
          <lower>-0.523598776</lower>
          <upper>0.523598776</upper>
        </limit>
        <dynamics>
          <damping>0.01</damping>
        </dynamics>
      </axis>
    </joint>
    <joint name="joint1213" type="revolute">
      <pose degrees="true" relative_to="link12">0.016636313 0 0 0 0 0</pose>
      <parent>link12</parent>
      <child>link13</child>
      <axis>
        <xyz>0 0 1</xyz>
        <limit>
          <lower>-0.523598776</lower>
          <upper>0.523598776</upper>
        </limit>
        <dynamics>
          <damping>0.01</damping>
        </dynamics>
      </axis>
    </joint>
    <joint name="joint1314" type="revolute">
      <pose degrees="true" relative_to="link13">0.015168563 0 0 0 0 0</pose>
      <parent>link13</parent>
      <child>link14</child>
      <axis>
        <xyz>0 0 1</xyz>
        <limit>
          <lower>-0.523598776</lower>
          <upper>0.523598776</upper>
        </limit>
        <dynamics>
          <damping>0.01</damping>
        </dynamics>
      </axis>
    </joint>
    <joint name="joint1415" type="revolute">
      <pose degrees="true" relative_to="link14">0.013830305 0 0 0 0 0</pose>
      <parent>link14</parent>
      <child>link15</child>
      <axis>
        <xyz>0 0 1</xyz>
        <limit>
          <lower>-0.523598776</lower>
          <upper>0.523598776</upper>
        </limit>
        <dynamics>
          <damping>0.01</damping>
        </dynamics>
      </axis>
    </joint>
    <joint name="joint1516" type="revolute">
      <pose degrees="true" relative_to="link15">0.012610117 0 0 0 0 0</pose>
      <parent>link15</parent>
      <child>link16</child>
      <axis>
        <xyz>0 0 1</xyz>
        <limit>
          <lower>-0.523598776</lower>
          <upper>0.523598776</upper>
        </limit>
        <dynamics>
          <damping>0.01</damping>
        </dynamics>
      </axis>
    </joint>
    <joint name="joint1617" type="revolute">
      <pose degrees="true" relative_to="link16">0.011497580 0 0 0 0 0</pose>
      <parent>link16</parent>
      <child>link17</child>
      <axis>
        <xyz>0 0 1</xyz>
        <limit>
          <lower>-0.523598776</lower>
          <upper>0.523598776</upper>
        </limit>
        <dynamics>
          <damping>0.01</damping>
        </dynamics>
      </axis>
    </joint>
    <joint name="joint1718" type="revolute">
      <pose degrees="true" relative_to="link17">0.010483198 0 0 0 0 0</pose>
      <parent>link17</parent>
      <child>link18</child>
      <axis>
        <xyz>0 0 1</xyz>
        <limit>
          <lower>-0.523598776</lower>
          <upper>0.523598776</upper>
        </limit>
        <dynamics>
          <damping>0.01</damping>
        </dynamics>
      </axis>
    </joint>
    <joint name="joint1819" type="revolute">
      <pose degrees="true" relative_to="link18">0.009558310 0 0 0 0 0</pose>
      <parent>link18</parent>
      <child>link19</child>
      <axis>
        <xyz>0 0 1</xyz>
        <limit>
          <lower>-0.523598776</lower>
          <upper>0.523598776</upper>
        </limit>
        <dynamics>
          <damping>0.01</damping>
        </dynamics>
      </axis>
    </joint>
    <joint name="joint1920" type="revolute">
      <pose degrees="true" relative_to="link19">0.008715021 0 0 0 0 0</pose>
      <parent>link19</parent>
      <child>link20</child>
      <axis>
        <xyz>0 0 1</xyz>
        <limit>
          <lower>-0.523598776</lower>
          <upper>0.523598776</upper>
        </limit>
        <dynamics>
          <damping>0.01</damping>
        </dynamics>
      </axis>
    </joint>
    <joint name="joint2021" type="revolute">
      <pose degrees="true" relative_to="link20">0.007946132 0 0 0 0 0</pose>
      <parent>link20</parent>
      <child>link21</child>
      <axis>
        <xyz>0 0 1</xyz>
        <limit>
          <lower>-0.523598776</lower>
          <upper>0.523598776</upper>
        </limit>
        <dynamics>
          <damping>0.01</damping>
        </dynamics>
      </axis>
    </joint>
    <joint name="joint2122" type="revolute">
      <pose degrees="true" relative_to="link21">0.007245079 0 0 0 0 0</pose>
      <parent>link21</parent>
      <child>link22</child>
      <axis>
        <xyz>0 0 1</xyz>
        <limit>
          <lower>-0.523598776</lower>
          <upper>0.523598776</upper>
        </limit>
        <dynamics>
          <damping>0.01</damping>
        </dynamics>
      </axis>
    </joint>
    <joint name="joint2223" type="revolute">
      <pose degrees="true" relative_to="link22">0.006605876 0 0 0 0 0</pose>
      <parent>link22</parent>
      <child>link23</child>
      <axis>
        <xyz>0 0 1</xyz>
        <limit>
          <lower>-0.523598776</lower>
          <upper>0.523598776</upper>
        </limit>
        <dynamics>
          <damping>0.01</damping>
        </dynamics>
      </axis>
    </joint>
    <joint name="joint2324" type="revolute">
      <pose degrees="true" relative_to="link23">0.006023068 0 0 0 0 0</pose>
      <parent>link23</parent>
      <child>link24</child>
      <axis>
        <xyz>0 0 1</xyz>
        <limit>
          <lower>-0.523598776</lower>
          <upper>0.523598776</upper>
        </limit>
        <dynamics>
          <damping>0.01</damping>
        </dynamics>
      </axis>
    </joint>
  </model>
</sdf>
