<mujoco model="spiral_robot">
  <compiler angle="radian"/>
  <option gravity="0 0 0"/>
  <asset>
    <mesh name="baselink_1" file="baselink.stl" scale="0.001000000 0.001000000 0.001000000"/>
    <mesh name="baselink_2" file="baselink.stl" scale="0.000911774 0.000911774 0.000911774"/>
    <mesh name="baselink_3" file="baselink.stl" scale="0.000831332 0.000831332 0.000831332"/>
    <mesh name="baselink_4" file="baselink.stl" scale="0.000757987 0.000757987 0.000757987"/>
    <mesh name="baselink_5" file="baselink.stl" scale="0.000691113 0.000691113 0.000691113"/>
    <mesh name="baselink_6" file="baselink.stl" scale="0.000630139 0.000630139 0.000630139"/>
    <mesh name="baselink_7" file="baselink.stl" scale="0.000574545 0.000574545 0.000574545"/>
    <mesh name="baselink_8" file="baselink.stl" scale="0.000523855 0.000523855 0.000523855"/>
    <mesh name="baselink_9" file="baselink.stl" scale="0.000477638 0.000477638 0.000477638"/>
    <mesh name="baselink_10" file="baselink.stl" scale="0.000435498 0.000435498 0.000435498"/>
    <mesh name="baselink_11" file="baselink.stl" scale="0.000397076 0.000397076 0.000397076"/>
    <mesh name="baselink_12" file="baselink.stl" scale="0.000362043 0.000362043 0.000362043"/>
    <mesh name="baselink_13" file="baselink.stl" scale="0.000330102 0.000330102 0.000330102"/>
    <mesh name="baselink_14" file="baselink.stl" scale="0.000300978 0.000300978 0.000300978"/>
    <mesh name="baselink_15" file="baselink.stl" scale="0.000274424 0.000274424 0.000274424"/>
    <mesh name="baselink_16" file="baselink.stl" scale="0.000250213 0.000250213 0.000250213"/>
    <mesh name="baselink_17" file="baselink.stl" scale="0.000228138 0.000228138 0.000228138"/>
    <mesh name="baselink_18" file="baselink.stl" scale="0.000208010 0.000208010 0.000208010"/>
    <mesh name="baselink_19" file="baselink.stl" scale="0.000189658 0.000189658 0.000189658"/>
    <mesh name="baselink_20" file="baselink.stl" scale="0.000172926 0.000172926 0.000172926"/>
    <mesh name="baselink_21" file="baselink.stl" scale="0.000157669 0.000157669 0.000157669"/>
    <mesh name="baselink_22" file="baselink.stl" scale="0.000143759 0.000143759 0.000143759"/>
    <mesh name="baselink_23" file="baselink.stl" scale="0.000131075 0.000131075 0.000131075"/>
    <mesh name="baselink_24" file="baselink.stl" scale="0.000119511 0.000119511 0.000119511"/>
    <texture name="texplane" type="2d" builtin="checker" rgb1=".2 .3 .4" rgb2=".1 0.15 0.2" width="512" height="512" mark="cross" markrgb=".8 .8 .8"/>
    <material name="matplane" reflectance="0.3" texture="texplane" texrepeat="1 1" texuniform="true"/>
  </asset>
  <worldbody>
    <geom name="ground" type="plane" size="10 10 1" pos="0 0 0" quat="1 0 0 0" material="matplane" condim="1"/>
    <light pos="1 0.5 0.7" dir="-1 -0.5 -1" directional="true" castshadow="false" diffuse="1 1 1" specular="0.3 0.3 0.3"/>
    <body name="link1" pos="0 0 0.464082120">
      <geom type="mesh" mesh="baselink_1"/>
      <site name="s1_1" pos="0.000000000 0.036394210 0.016795002" size="0.001000 0.001000 0.001000"/>
      <site name="s1_2" pos="0.000000000 0.034423562 0.042801474" size="0.001000 0.001000 0.001000"/>
      <site name="s1_3" pos="0.000000000 -0.036394210 0.016795002" size="0.001000 0.001000 0.001000"/>
      <site name="s1_4" pos="0.000000000 -0.034423562 0.042801474" size="0.001000 0.001000 0.001000"/>
      <body name="link2" pos="0 0 0.045951152">
        <joint type="hinge" axis="1 0 0" range="-0.523598776 0.523598776" stiffness="50.000000" damping="20.000000"/>
        <geom type="mesh" mesh="baselink_2"/>
        <site name="s2_1" pos="0.000000000 0.033183304 0.015313251" size="0.000912 0.000912 0.000912"/>
        <site name="s2_2" pos="0.000000000 0.031386518 0.039025283" size="0.000912 0.000912 0.000912"/>
        <site name="s2_3" pos="0.000000000 -0.033183304 0.015313251" size="0.000912 0.000912 0.000912"/>
        <site name="s2_4" pos="0.000000000 -0.031386518 0.039025283" size="0.000912 0.000912 0.000912"/>
      <body name="link3" pos="0 0 0.041897079">
        <joint type="hinge" axis="1 0 0" range="-0.523598776 0.523598776" stiffness="41.566617" damping="18.235486"/>
        <geom type="mesh" mesh="baselink_3"/>
        <site name="s3_1" pos="0.000000000 0.030255683 0.013962228" size="0.000831 0.000831 0.000831"/>
        <site name="s3_2" pos="0.000000000 0.028617420 0.035582249" size="0.000831 0.000831 0.000831"/>
        <site name="s3_3" pos="0.000000000 -0.030255683 0.013962228" size="0.000831 0.000831 0.000831"/>
        <site name="s3_4" pos="0.000000000 -0.028617420 0.035582249" size="0.000831 0.000831 0.000831"/>
      <body name="link4" pos="0 0 0.038200679">
        <joint type="hinge" axis="1 0 0" range="-0.523598776 0.523598776" stiffness="34.555672" damping="16.626647"/>
        <geom type="mesh" mesh="baselink_4"/>
        <site name="s4_1" pos="0.000000000 0.027586354 0.012730400" size="0.000758 0.000758 0.000758"/>
        <site name="s4_2" pos="0.000000000 0.026092627 0.032442980" size="0.000758 0.000758 0.000758"/>
        <site name="s4_3" pos="0.000000000 -0.027586354 0.012730400" size="0.000758 0.000758 0.000758"/>
        <site name="s4_4" pos="0.000000000 -0.026092627 0.032442980" size="0.000758 0.000758 0.000758"/>
      <body name="link5" pos="0 0 0.034830396">
        <joint type="hinge" axis="1 0 0" range="-0.523598776 0.523598776" stiffness="28.727247" damping="15.159749"/>
        <geom type="mesh" mesh="baselink_5"/>
        <site name="s5_1" pos="0.000000000 0.025152528 0.011607252" size="0.000691 0.000691 0.000691"/>
        <site name="s5_2" pos="0.000000000 0.023790586 0.029580674" size="0.000691 0.000691 0.000691"/>
        <site name="s5_3" pos="0.000000000 -0.025152528 0.011607252" size="0.000691 0.000691 0.000691"/>
        <site name="s5_4" pos="0.000000000 -0.023790586 0.029580674" size="0.000691 0.000691 0.000691"/>
      <body name="link6" pos="0 0 0.031757459">
        <joint type="hinge" axis="1 0 0" range="-0.523598776 0.523598776" stiffness="23.881890" damping="13.822269"/>
        <geom type="mesh" mesh="baselink_6"/>
        <site name="s6_1" pos="0.000000000 0.022933428 0.010583193" size="0.000630 0.000630 0.000630"/>
        <site name="s6_2" pos="0.000000000 0.021691645 0.026970898" size="0.000630 0.000630 0.000630"/>
        <site name="s6_3" pos="0.000000000 -0.022933428 0.010583193" size="0.000630 0.000630 0.000630"/>
        <site name="s6_4" pos="0.000000000 -0.021691645 0.026970898" size="0.000630 0.000630 0.000630"/>
      <body name="link7" pos="0 0 0.028955634">
        <joint type="hinge" axis="1 0 0" range="-0.523598776 0.523598776" stiffness="19.853787" damping="12.602789"/>
        <geom type="mesh" mesh="baselink_7"/>
        <site name="s7_1" pos="0.000000000 0.020910109 0.009649483" size="0.000575 0.000575 0.000575"/>
        <site name="s7_2" pos="0.000000000 0.019777884 0.024591371" size="0.000575 0.000575 0.000575"/>
        <site name="s7_3" pos="0.000000000 -0.020910109 0.009649483" size="0.000575 0.000575 0.000575"/>
        <site name="s7_4" pos="0.000000000 -0.019777884 0.024591371" size="0.000575 0.000575 0.000575"/>
      <body name="link8" pos="0 0 0.026401003">
        <joint type="hinge" axis="1 0 0" range="-0.523598776 0.523598776" stiffness="16.505095" damping="11.490899"/>
        <geom type="mesh" mesh="baselink_8"/>
        <site name="s8_1" pos="0.000000000 0.019065300 0.008798151" size="0.000524 0.000524 0.000524"/>
        <site name="s8_2" pos="0.000000000 0.018032965 0.022421779" size="0.000524 0.000524 0.000524"/>
        <site name="s8_3" pos="0.000000000 -0.019065300 0.008798151" size="0.000524 0.000524 0.000524"/>
        <site name="s8_4" pos="0.000000000 -0.018032965 0.022421779" size="0.000524 0.000524 0.000524"/>
      <body name="link9" pos="0 0 0.024071755">
        <joint type="hinge" axis="1 0 0" range="-0.523598776 0.523598776" stiffness="13.721219" damping="10.477106"/>
        <geom type="mesh" mesh="baselink_9"/>
        <site name="s9_1" pos="0.000000000 0.017383250 0.008021928" size="0.000478 0.000478 0.000478"/>
        <site name="s9_2" pos="0.000000000 0.016441994 0.020443602" size="0.000478 0.000478 0.000478"/>
        <site name="s9_3" pos="0.000000000 -0.017383250 0.008021928" size="0.000478 0.000478 0.000478"/>
        <site name="s9_4" pos="0.000000000 -0.016441994 0.020443602" size="0.000478 0.000478 0.000478"/>
      <body name="link10" pos="0 0 0.021948007">
        <joint type="hinge" axis="1 0 0" range="-0.523598776 0.523598776" stiffness="11.406893" damping="9.552756"/>
        <geom type="mesh" mesh="baselink_10"/>
        <site name="s10_1" pos="0.000000000 0.015849600 0.007314187" size="0.000435 0.000435 0.000435"/>
        <site name="s10_2" pos="0.000000000 0.014991387 0.018639950" size="0.000435 0.000435 0.000435"/>
        <site name="s10_3" pos="0.000000000 -0.015849600 0.007314187" size="0.000435 0.000435 0.000435"/>
        <site name="s10_4" pos="0.000000000 -0.014991387 0.018639950" size="0.000435 0.000435 0.000435"/>
      <body name="link11" pos="0 0 0.020011628">
        <joint type="hinge" axis="1 0 0" range="-0.523598776 0.523598776" stiffness="9.482919" damping="8.709957"/>
        <geom type="mesh" mesh="baselink_11"/>
        <site name="s11_1" pos="0.000000000 0.014451258 0.006668888" size="0.000397 0.000397 0.000397"/>
        <site name="s11_2" pos="0.000000000 0.013668761 0.016995427" size="0.000397 0.000397 0.000397"/>
        <site name="s11_3" pos="0.000000000 -0.014451258 0.006668888" size="0.000397 0.000397 0.000397"/>
        <site name="s11_4" pos="0.000000000 -0.013668761 0.016995427" size="0.000397 0.000397 0.000397"/>
      <body name="link12" pos="0 0 0.018246088">
        <joint type="hinge" axis="1 0 0" range="-0.523598776 0.523598776" stiffness="7.883457" damping="7.941515"/>
        <geom type="mesh" mesh="baselink_12"/>
        <site name="s12_1" pos="0.000000000 0.013176285 0.006080520" size="0.000362 0.000362 0.000362"/>
        <site name="s12_2" pos="0.000000000 0.012462825 0.015495993" size="0.000362 0.000362 0.000362"/>
        <site name="s12_3" pos="0.000000000 -0.013176285 0.006080520" size="0.000362 0.000362 0.000362"/>
        <site name="s12_4" pos="0.000000000 -0.012462825 0.015495993" size="0.000362 0.000362 0.000362"/>
      <body name="link13" pos="0 0 0.016636313">
        <joint type="hinge" axis="1 0 0" range="-0.523598776 0.523598776" stiffness="6.553773" damping="7.240869"/>
        <geom type="mesh" mesh="baselink_13"/>
        <site name="s13_1" pos="0.000000000 0.012013798 0.005544062" size="0.000330 0.000330 0.000330"/>
        <site name="s13_2" pos="0.000000000 0.011363283 0.014128848" size="0.000330 0.000330 0.000330"/>
        <site name="s13_3" pos="0.000000000 -0.012013798 0.005544062" size="0.000330 0.000330 0.000330"/>
        <site name="s13_4" pos="0.000000000 -0.011363283 0.014128848" size="0.000330 0.000330 0.000330"/>
      <body name="link14" pos="0 0 0.015168563">
        <joint type="hinge" axis="1 0 0" range="-0.523598776 0.523598776" stiffness="5.448363" damping="6.602038"/>
        <geom type="mesh" mesh="baselink_14"/>
        <site name="s14_1" pos="0.000000000 0.010953872 0.005054933" size="0.000301 0.000301 0.000301"/>
        <site name="s14_2" pos="0.000000000 0.010360749 0.012882320" size="0.000301 0.000301 0.000301"/>
        <site name="s14_3" pos="0.000000000 -0.010953872 0.005054933" size="0.000301 0.000301 0.000301"/>
        <site name="s14_4" pos="0.000000000 -0.010360749 0.012882320" size="0.000301 0.000301 0.000301"/>
      <body name="link15" pos="0 0 0.013830305">
        <joint type="hinge" axis="1 0 0" range="-0.523598776 0.523598776" stiffness="4.529400" damping="6.019568"/>
        <geom type="mesh" mesh="baselink_15"/>
        <site name="s15_1" pos="0.000000000 0.009987459 0.004608958" size="0.000274 0.000274 0.000274"/>
        <site name="s15_2" pos="0.000000000 0.009446665 0.011745768" size="0.000274 0.000274 0.000274"/>
        <site name="s15_3" pos="0.000000000 -0.009987459 0.004608958" size="0.000274 0.000274 0.000274"/>
        <site name="s15_4" pos="0.000000000 -0.009446665 0.011745768" size="0.000274 0.000274 0.000274"/>
      <body name="link16" pos="0 0 0.012610117">
        <joint type="hinge" axis="1 0 0" range="-0.523598776 0.523598776" stiffness="3.765437" damping="5.488488"/>
        <geom type="mesh" mesh="baselink_16"/>
        <site name="s16_1" pos="0.000000000 0.009106308 0.004202329" size="0.000250 0.000250 0.000250"/>
        <site name="s16_2" pos="0.000000000 0.008613226 0.010709489" size="0.000250 0.000250 0.000250"/>
        <site name="s16_3" pos="0.000000000 -0.009106308 0.004202329" size="0.000250 0.000250 0.000250"/>
        <site name="s16_4" pos="0.000000000 -0.008613226 0.010709489" size="0.000250 0.000250 0.000250"/>
      <body name="link17" pos="0 0 0.011497580">
        <joint type="hinge" axis="1 0 0" range="-0.523598776 0.523598776" stiffness="3.130330" damping="5.004262"/>
        <geom type="mesh" mesh="baselink_17"/>
        <site name="s17_1" pos="0.000000000 0.008302897 0.003831576" size="0.000228 0.000228 0.000228"/>
        <site name="s17_2" pos="0.000000000 0.007853318 0.009764637" size="0.000228 0.000228 0.000228"/>
        <site name="s17_3" pos="0.000000000 -0.008302897 0.003831576" size="0.000228 0.000228 0.000228"/>
        <site name="s17_4" pos="0.000000000 -0.007853318 0.009764637" size="0.000228 0.000228 0.000228"/>
      <body name="link18" pos="0 0 0.010483198">
        <joint type="hinge" axis="1 0 0" range="-0.523598776 0.523598776" stiffness="2.602344" damping="4.562757"/>
        <geom type="mesh" mesh="baselink_18"/>
        <site name="s18_1" pos="0.000000000 0.007570368 0.003493532" size="0.000208 0.000208 0.000208"/>
        <site name="s18_2" pos="0.000000000 0.007160453 0.008903145" size="0.000208 0.000208 0.000208"/>
        <site name="s18_3" pos="0.000000000 -0.007570368 0.003493532" size="0.000208 0.000208 0.000208"/>
        <site name="s18_4" pos="0.000000000 -0.007160453 0.008903145" size="0.000208 0.000208 0.000208"/>
      <body name="link19" pos="0 0 0.009558310">
        <joint type="hinge" axis="1 0 0" range="-0.523598776 0.523598776" stiffness="2.163413" damping="4.160205"/>
        <geom type="mesh" mesh="baselink_19"/>
        <site name="s19_1" pos="0.000000000 0.006902467 0.003185313" size="0.000190 0.000190 0.000190"/>
        <site name="s19_2" pos="0.000000000 0.006528717 0.008117658" size="0.000190 0.000190 0.000190"/>
        <site name="s19_3" pos="0.000000000 -0.006902467 0.003185313" size="0.000190 0.000190 0.000190"/>
        <site name="s19_4" pos="0.000000000 -0.006528717 0.008117658" size="0.000190 0.000190 0.000190"/>
      <body name="link20" pos="0 0 0.008715021">
        <joint type="hinge" axis="1 0 0" range="-0.523598776 0.523598776" stiffness="1.798515" damping="3.793168"/>
        <geom type="mesh" mesh="baselink_20"/>
        <site name="s20_1" pos="0.000000000 0.006293492 0.002904286" size="0.000173 0.000173 0.000173"/>
        <site name="s20_2" pos="0.000000000 0.005952716 0.007401472" size="0.000173 0.000173 0.000173"/>
        <site name="s20_3" pos="0.000000000 -0.006293492 0.002904286" size="0.000173 0.000173 0.000173"/>
        <site name="s20_4" pos="0.000000000 -0.005952716 0.007401472" size="0.000173 0.000173 0.000173"/>
      <body name="link21" pos="0 0 0.007946132">
        <joint type="hinge" axis="1 0 0" range="-0.523598776 0.523598776" stiffness="1.495164" damping="3.458513"/>
        <geom type="mesh" mesh="baselink_21"/>
        <site name="s21_1" pos="0.000000000 0.005738244 0.002648054" size="0.000158 0.000158 0.000158"/>
        <site name="s21_2" pos="0.000000000 0.005427533 0.006748472" size="0.000158 0.000158 0.000158"/>
        <site name="s21_3" pos="0.000000000 -0.005738244 0.002648054" size="0.000158 0.000158 0.000158"/>
        <site name="s21_4" pos="0.000000000 -0.005427533 0.006748472" size="0.000158 0.000158 0.000158"/>
      <body name="link22" pos="0 0 0.007245079">
        <joint type="hinge" axis="1 0 0" range="-0.523598776 0.523598776" stiffness="1.242978" damping="3.153383"/>
        <geom type="mesh" mesh="baselink_22"/>
        <site name="s22_1" pos="0.000000000 0.005231983 0.002414427" size="0.000144 0.000144 0.000144"/>
        <site name="s22_2" pos="0.000000000 0.004948685 0.006153083" size="0.000144 0.000144 0.000144"/>
        <site name="s22_3" pos="0.000000000 -0.005231983 0.002414427" size="0.000144 0.000144 0.000144"/>
        <site name="s22_4" pos="0.000000000 -0.004948685 0.006153083" size="0.000144 0.000144 0.000144"/>
      <body name="link23" pos="0 0 0.006605876">
        <joint type="hinge" axis="1 0 0" range="-0.523598776 0.523598776" stiffness="1.033328" damping="2.875173"/>
        <geom type="mesh" mesh="baselink_23"/>
        <site name="s23_1" pos="0.000000000 0.004770388 0.002201413" size="0.000131 0.000131 0.000131"/>
        <site name="s23_2" pos="0.000000000 0.004512084 0.005610223" size="0.000131 0.000131 0.000131"/>
        <site name="s23_3" pos="0.000000000 -0.004770388 0.002201413" size="0.000131 0.000131 0.000131"/>
        <site name="s23_4" pos="0.000000000 -0.004512084 0.005610223" size="0.000131 0.000131 0.000131"/>
      <body name="link24" pos="0 0 0.006023068">
        <joint type="hinge" axis="1 0 0" range="-0.523598776 0.523598776" stiffness="0.859039" damping="2.621509"/>
        <geom type="mesh" mesh="baselink_24"/>
        <site name="s24_1" pos="0.000000000 0.004349517 0.002007191" size="0.000120 0.000120 0.000120"/>
        <site name="s24_2" pos="0.000000000 0.004114002 0.005115257" size="0.000120 0.000120 0.000120"/>
        <site name="s24_3" pos="0.000000000 -0.004349517 0.002007191" size="0.000120 0.000120 0.000120"/>
        <site name="s24_4" pos="0.000000000 -0.004114002 0.005115257" size="0.000120 0.000120 0.000120"/>
      </body>
      </body>
      </body>
      </body>
      </body>
      </body>
      </body>
      </body>
      </body>
      </body>
      </body>
      </body>
      </body>
      </body>
      </body>
      </body>
      </body>
      </body>
      </body>
      </body>
      </body>
      </body>
      </body>
    </body>
  </worldbody>
  <tendon>
    <spatial name="tendon1" width="0.0007" frictionloss="0.1" rgba=".95 .3 .3 1" limited="true" range="0.185632848 1.160205301">
      <site site="s1_1"/>
      <site site="s1_2"/>
      <site site="s2_1"/>
      <site site="s2_2"/>
      <site site="s3_1"/>
      <site site="s3_2"/>
      <site site="s4_1"/>
      <site site="s4_2"/>
      <site site="s5_1"/>
      <site site="s5_2"/>
      <site site="s6_1"/>
      <site site="s6_2"/>
      <site site="s7_1"/>
      <site site="s7_2"/>
      <site site="s8_1"/>
      <site site="s8_2"/>
      <site site="s9_1"/>
      <site site="s9_2"/>
      <site site="s10_1"/>
      <site site="s10_2"/>
      <site site="s11_1"/>
      <site site="s11_2"/>
      <site site="s12_1"/>
      <site site="s12_2"/>
      <site site="s13_1"/>
      <site site="s13_2"/>
      <site site="s14_1"/>
      <site site="s14_2"/>
      <site site="s15_1"/>
      <site site="s15_2"/>
      <site site="s16_1"/>
      <site site="s16_2"/>
      <site site="s17_1"/>
      <site site="s17_2"/>
      <site site="s18_1"/>
      <site site="s18_2"/>
      <site site="s19_1"/>
      <site site="s19_2"/>
      <site site="s20_1"/>
      <site site="s20_2"/>
      <site site="s21_1"/>
      <site site="s21_2"/>
      <site site="s22_1"/>
      <site site="s22_2"/>
      <site site="s23_1"/>
      <site site="s23_2"/>
      <site site="s24_1"/>
      <site site="s24_2"/>
    </spatial>
    <spatial name="tendon2" width="0.0007" frictionloss="0.1" rgba=".95 .3 .3 1" limited="true" range="0.185632848 1.160205301">
      <site site="s1_3"/>
      <site site="s1_4"/>
      <site site="s2_3"/>
      <site site="s2_4"/>
      <site site="s3_3"/>
      <site site="s3_4"/>
      <site site="s4_3"/>
      <site site="s4_4"/>
      <site site="s5_3"/>
      <site site="s5_4"/>
      <site site="s6_3"/>
      <site site="s6_4"/>
      <site site="s7_3"/>
      <site site="s7_4"/>
      <site site="s8_3"/>
      <site site="s8_4"/>
      <site site="s9_3"/>
      <site site="s9_4"/>
      <site site="s10_3"/>
      <site site="s10_4"/>
      <site site="s11_3"/>
      <site site="s11_4"/>
      <site site="s12_3"/>
      <site site="s12_4"/>
      <site site="s13_3"/>
      <site site="s13_4"/>
      <site site="s14_3"/>
      <site site="s14_4"/>
      <site site="s15_3"/>
      <site site="s15_4"/>
      <site site="s16_3"/>
      <site site="s16_4"/>
      <site site="s17_3"/>
      <site site="s17_4"/>
      <site site="s18_3"/>
      <site site="s18_4"/>
      <site site="s19_3"/>
      <site site="s19_4"/>
      <site site="s20_3"/>
      <site site="s20_4"/>
      <site site="s21_3"/>
      <site site="s21_4"/>
      <site site="s22_3"/>
      <site site="s22_4"/>
      <site site="s23_3"/>
      <site site="s23_4"/>
      <site site="s24_3"/>
      <site site="s24_4"/>
    </spatial>
  </tendon>
  <actuator>
    <muscle name="act1" tendon="tendon1" ctrllimited="true" ctrlrange="0 1" force="5" lengthrange="0.185632848 1.160205301"/>
    <muscle name="act2" tendon="tendon2" ctrllimited="true" ctrlrange="0 1" force="5" lengthrange="0.185632848 1.160205301"/>
  </actuator>
</mujoco>
